Crash during transplanting functions, after 0.071 minutes.
Transformation Failed
[Errno 2] No such file or directory: '/data/backport/linux/135/pa/block/arch/x86/include'
Unexpected error during transplanting functions.
Runtime Error
Error. Exiting...
Traceback (most recent call last):
  File "/FixMorph/app/phases/weaving.py", line 25, in safe_exec
    result = function_def()
  File "/FixMorph/app/phases/weaving.py", line 63, in transplant_missing_functions
    modified_source_list)
  File "/FixMorph/app/tools/weaver.py", line 377, in weave_functions
    source_path_a)
  File "/FixMorph/app/tools/extractor.py", line 79, in extract_complete_function_node
    search_dir_file_list = get_file_list(search_dir)
  File "/FixMorph/app/common/utilities.py", line 181, in get_file_list
    current_file_list = os.listdir(dir_name)
FileNotFoundError: [Errno 2] No such file or directory: '/data/backport/linux/135/pa/block/arch/x86/include'

During handling of the above exception, another exception occurred:

Traceback (most recent call last):
  File "/FixMorph/app/main.py", line 184, in main
    run(sys.argv[1:])
  File "/FixMorph/app/main.py", line 157, in run
    weaving.start()
  File "/FixMorph/app/phases/weaving.py", line 206, in start
    safe_exec(transplant_missing_functions, "transplanting functions")
  File "/FixMorph/app/phases/weaving.py", line 33, in safe_exec
    error_exit(exception, "Unexpected error during " + description + ".")
  File "/FixMorph/app/common/utilities.py", line 83, in error_exit
    raise Exception("Error. Exiting...")
Exception: Error. Exiting...

FixMorph exited with an error after 22.429 minutes

